Workbook

Sheet Code Guide
A2: The codes are derived from the Pillar, Objective and Category
A3: The first number is the pillar, second number objective according to project and SMART budget, third number is category
A5: Pillars:
A6: 1 | B6: Supporting CSOS
A7: 2 | B7: Strengthening Communities
A8: 3 | B8: Building the field of community philanthropy
A9: 4 | B9: Ovearheads
A10: Objectives are project specific
A14: Categories
A15: 1 | B15: Grants & Capacity Strengthening
A16: =A15+1 -> 2 | B16: Training & Learning (Capacity development)
A17: =A16+1 -> 3 | B17: Community Engagement & Field Work (Capacity Development)
A18: =A17+1 -> 4 | B18: Operations & Governance (Overheads)
A19: =A18+1 -> 5 | B19: Philanthropy, Communications & Visibility
A20: =A19+1 -> 6 | B20: Consultancy & Professional Services

Sheet Budget Summary
A2: Zambian Governance Foundation Ltd.
A3: 2026 Workplan budget summary
A4: Funding Source | B4: Strategic Pillar | C4: Q1 | D4: Q2 | E4: Q3 | F4: Q4 | G4: Total Annual Budget
A5: Comic Relief | B5: Supporting CSO-Grants & Contracts Management | C5: ='Comic Relief'!L7+'Comic Relief'!L8+'Comic Relief'!L9+'Comic Relief'!L10+'Comic Relief'!L18+'Comic Relief'!L34+'Comic Relief'!L35+'Comic Relief'!L36+'Comic Relief'!L37 -> 15708940 | D5: ='Comic Relief'!M7+'Comic Relief'!M8+'Comic Relief'!M9+'Comic Relief'!M10+'Comic Relief'!M18+'Comic Relief'!M34+'Comic Relief'!M35+'Comic Relief'!M36+'Comic Relief'!M37 -> 345286.67 | E5: ='Comic Relief'!N7+'Comic Relief'!N8+'Comic Relief'!N9+'Comic Relief'!N10+'Comic Relief'!N18+'Comic Relief'!N34+'Comic Relief'!N35+'Comic Relief'!N36+'Comic Relief'!N37 -> 5581286.7 | F5: ='Comic Relief'!O7+'Comic Relief'!O8+'Comic Relief'!O9+'Comic Relief'!O10+'Comic Relief'!O18+'Comic Relief'!O34+'Comic Relief'!O35+'Comic Relief'!O36+'Comic Relief'!O37 -> 9644686.7 | G5: =SUM(C5:F5) -> 31280200
B6: Supporting CSO-Capacity Development | C6: =SUM('Comic Relief'!L7:L37)-C5 -> 2856777.5 | D6: =SUM('Comic Relief'!M7:M37)-D5 -> 5816661.7 | E6: =SUM('Comic Relief'!N7:N37)-E5 -> 5079062 | F6: =SUM('Comic Relief'!O7:O37)-F5 -> 2585820.9 | G6: =SUM(C6:F6) -> 16338322
B7: Building the field of community philanthropy | C7: =SUM('Comic Relief'!L38:L52) -> 633944.99 | D7: =SUM('Comic Relief'!M38:M52) -> 759194.99 | E7: =SUM('Comic Relief'!N38:N52) -> 607260 | F7: =SUM('Comic Relief'!O38:O52) -> 482520 | G7: =SUM(C7:F7) -> 2482920
B8: Operations | C8: =SUM('Comic Relief'!L54:L65) -> 2531305.3 | D8: =SUM('Comic Relief'!M54:M65) -> 2767419.2 | E8: =SUM('Comic Relief'!N54:N65) -> 2637419.2 | F8: =SUM('Comic Relief'!O54:O65) -> 2624919.2 | G8: =SUM(C8:F8) -> 10561063
A9: Total-Comic Relief | C9: =SUM(C6:C8) -> 6022027.8 | D9: =SUM(D6:D8) -> 9343275.8 | E9: =SUM(E6:E8) -> 8323741.2 | F9: =SUM(F6:F8) -> 5693260.1 | G9: =SUM(G5:G8) -> 60662505
A10: MOTTII | B10: Strengthening Communities-Grants & Contract management | C10: =MOTTIII!L12+MOTTIII!L14+MOTTIII!L15+MOTTIII!L16+MOTTIII!L17+MOTTIII!L18+MOTTIII!L19+MOTTIII!L29 -> 390059.67 | D10: =MOTTIII!M12+MOTTIII!M14+MOTTIII!M15+MOTTIII!M16+MOTTIII!M17+MOTTIII!M18+MOTTIII!M19+MOTTIII!M29 -> 46987.667 | E10: =MOTTIII!N12+MOTTIII!N14+MOTTIII!N15+MOTTIII!N16+MOTTIII!N17+MOTTIII!N18+MOTTIII!N19+MOTTIII!N29 -> 167505.67 | F10: =MOTTIII!O12+MOTTIII!O14+MOTTIII!O15+MOTTIII!O16+MOTTIII!O17+MOTTIII!O18+MOTTIII!O19+MOTTIII!O29 -> 42500 | G10: =SUM(C10:F10) -> 647053
B11: Strengthening Communities-Capacity Development | C11: =SUM(MOTTIII!L7:L30)-C10 -> 613530.33 | D11: =SUM(MOTTIII!M7:M30)-D10 -> 340591.33 | E11: =SUM(MOTTIII!N7:N30)-E10 -> 24509.333 | G11: =SUM(C11:F11) -> 978631
B12: Building the field of community philanthropy | C12: =MOTTIII!L33+MOTTIII!L35+MOTTIII!L36 -> 248260 | D12: =MOTTIII!M31+MOTTIII!M32+MOTTIII!M34 -> 234920 | E12: =SUM(MOTTIII!N31:N36) -> 15000 | G12: =SUM(C12:F12) -> 498180
B13: Operations | C13: =MOTTIII!L37+MOTTIII!L38 -> 474498 | D13: =MOTTIII!M37+MOTTIII!M38 -> 474498 | E13: =MOTTIII!N37+MOTTIII!N38 -> 474498 | G13: =SUM(C13:F13) -> 1423494
A14: Total-MoTT | C14: =SUM(C11:C13) -> 1336288.3 | D14: =SUM(D11:D13) -> 1050009.3 | E14: =SUM(E11:E13) -> 514007.33 | F14: =SUM(F11:F13) -> 0 | G14: =SUM(G10:G13) -> 3547358
A15: KaluluII | B15: Strengthening Communities-Grants & Contract management | C15: =KaluluII!L7+KaluluII!L8+KaluluII!L18+KaluluII!L19+KaluluII!L24 -> 211289.99 | D15: =KaluluII!M7+KaluluII!M8+KaluluII!M18+KaluluII!M19+KaluluII!M24 -> 236270 | E15: =KaluluII!N7+KaluluII!N8+KaluluII!N18+KaluluII!N19+KaluluII!N24 -> 149570 | F15: =KaluluII!O7+KaluluII!O8+KaluluII!O18+KaluluII!O19+KaluluII!O24 -> 19520 | G15: =SUM(C15:F15) -> 616649.99
B16: Strengthening Communities-Capacity Development | C16: =+KaluluII!L9+KaluluII!L10+KaluluII!L11+KaluluII!L12+KaluluII!L14+KaluluII!L15+KaluluII!L17+KaluluII!L20+KaluluII!L23 -> 152830 | D16: =+KaluluII!M9+KaluluII!M10+KaluluII!M11+KaluluII!M12+KaluluII!M14+KaluluII!M15+KaluluII!M17+KaluluII!M20+KaluluII!M23 -> 101470 | E16: =+KaluluII!N9+KaluluII!N10+KaluluII!N11+KaluluII!N12+KaluluII!N14+KaluluII!N15+KaluluII!N17+KaluluII!N20+KaluluII!N23 -> 67670 | F16: =+KaluluII!O9+KaluluII!O10+KaluluII!O11+KaluluII!O12+KaluluII!O14+KaluluII!O15+KaluluII!O17+KaluluII!O20+KaluluII!O23 -> 48610 | G16: =SUM(C16:F16) -> 370580
B17: Building the field of community philanthropy | C17: =KaluluII!L22+KaluluII!L21+KaluluII!L16+KaluluII!L13 -> 13650 | D17: =KaluluII!M22+KaluluII!M21+KaluluII!M16+KaluluII!M13 -> 51250 | E17: =KaluluII!N22+KaluluII!N21+KaluluII!N16+KaluluII!N13 -> 51250 | F17: =KaluluII!O22+KaluluII!O21+KaluluII!O16+KaluluII!O13 -> 13650 | G17: =SUM(C17:F17) -> 129800
B18: Operations | C18: =KaluluII!L26+KaluluII!L27 -> 505943.02 | D18: =KaluluII!M26+KaluluII!M27 -> 544388.59 | E18: =KaluluII!N26+KaluluII!N27 -> 535953.59 | F18: =KaluluII!O26+KaluluII!O27 -> 522883.89 | G18: =SUM(C18:F18) -> 2109169.1
A19: Total-Kalulu | C19: =SUM(C16:C18) -> 672423.02 | D19: =SUM(D16:D18) -> 697108.59 | E19: =SUM(E16:E18) -> 654873.59 | F19: =SUM(F16:F18) -> 585143.89 | G19: =SUM(G15:G18) -> 3226199.1
A20: ZGF | B20: Operations | C20: =ZGF!M11 -> 289000 | D20: =ZGF!N11 -> 328500 | E20: =ZGF!O11 -> 243500 | F20: =ZGF!P11 -> 243500 | G20: =SUM(C20:F20) -> 1104500
A21: Total-ZGF | C21: =SUM(C20) -> 289000 | D21: =SUM(D20) -> 328500 | E21: =SUM(E20) -> 243500 | F21: =SUM(F20) -> 243500 | G21: =SUM(G20) -> 1104500
A22: Total 2026 Annual Workplan budget | G22: =G9+G14+G19+G21 -> 68540562
A23: Budget Rates
A24: ZMW/USD-25
A25: ZMW/GBP-30
A26: ZMW/Euro-28

Sheet Comic Relief
A2: Zambian Governance Foundation Ltd.
A3: Comic Relief - 2026 Annual work plan budget
A4: 1 January to 31 December 2026
A5: Name of project: Shifting the Power programme
A6: Strategic Pillar | B6: Objective | C6: Activities | D6: Output/Indicator | E6: Category | F6: Activity Owner | G6: Quantity | H6: Unit Cost | I6: Total Budget-ZMW | J6: Total Budget-GBP | K6: Implementing Timeline | L6: Quarter1 | M6: Quarter2 | N6: Quarter3 | O6: Quarter4 | P6: Odoo Code | Q6: Odoo Category | R6: Legacy Suggested Code | S6: Legacy Suggested Description | T6: Funding Source | U6: Analytic Tags | V6: ZGF Code
A7: Supporting CSOS | B7: Objective 1: Support organisational strengthening (OS) interventions CSSF partners | C7: Disbursment of funds to 11 CSO's - November- 2026 | D7: 11 completed Grant Disbursements | E7: Grants & Contract Management | F7: Manager CSO Development | G7: 11 | H7: 800000 | I7: =G7*H7 -> 8800000 | J7: =I7/30 -> 293333.33 | K7: Q4 | O7: =I7 -> 8800000 | P7: 5100 | Q7: Grants & Capacity Strengthening | R7: 4000-010-004 | S7: Disbursements to Grant Partners | T7: Comic Relief | U7: Funding Source=Comic Relief; Strategic Pillar=Supporting CSOS; Programme Objective=Objective 1: Support organisational strengthening (OS) interventions CSSF partners; Activity=Disbursment of funds to 11 CSO's - November- 2026 | V7: 1.1.1
C8: Disbursment of funds to 7 CSO's - October - 2026 | D8: 7 completed Grant Disbursements | F8: Manager CSO Development | G8: 7 | H8: 750000 | I8: =G8*H8 -> 5250000 | J8: =I8/30 -> 175000 | K8: Q3 | N8: =I8 -> 5250000 | P8: 5100 | Q8: Grants & Capacity Strengthening | R8: 4000-010-004 | S8: Disbursements to Grant Partners | T8: Comic Relief | U8: Funding Source=Comic Relief; Activity=Disbursment of funds to 7 CSO's - October - 2026 | V8: 1.1.1
C9: Disbursment of funds to 20 CSO's -March- 2026 | D9: 20 completed Grant Disbursements | F9: Manager CSO Development | G9: 20 | H9: 750000 | I9: =G9*H9 -> 15000000 | J9: =I9/30 -> 500000 | K9: Q1 | L9: =I9 -> 15000000 | P9: 5100 | Q9: Grants & Capacity Strengthening | R9: 4000-010-004 | S9: Disbursements to Grant Partners | T9: Comic Relief | U9: Funding Source=Comic Relief; Activity=Disbursment of funds to 20 CSO's -March- 2026 | V9: 1.1.1
C10: Conduct introductory workshop for 38 CSO partners receiving the CSSF - 5 days - February 2026. | D10: 5 day Workshop for 38 CSOs | F10: Manager CSO Development | G10: 1 | H10: 708940 | I10: =G10*H10 -> 708940 | J10: =I10/30 -> 23631.333 | K10: Q1 | L10: =I10 -> 708940 | P10: 5100 | Q10: Grants & Capacity Strengthening | R10: 4000-010-004 | S10: Disbursements to Grant Partners | T10: Comic Relief | U10: Funding Source=Comic Relief; Activity=Conduct introductory workshop for 38 CSO partners receiving the CSSF - 5 days - February 2026.; ProjCode=1.3.1 | V10: 1.1.1
A11: Supporting CSOS | B11: Objective 1: Support organisational strengthening (OS) interventions CSSF partners | C11: Familiarisation visits to CSSF II & III CSOs (January - March 2026) | D11: 3 Trips to CSSF Partners | E11: Capacity development | F11: Manager CSO Development | G11: 3 | H11: 171686.67 | I11: =G11*H11 -> 515060 | J11: =I11/30 -> 17168.667 | K11: Q1 | L11: =I11 -> 515060 | P11: 5400 | Q11: Grants & Capacity Strengthening | R11: 4000-015-007-010 | S11: Conduct 5 day capacity building training | T11: Comic Relief | U11: Funding Source=Comic Relief; Strategic Pillar=Supporting CSOS; Programme Objective=Objective 1: Support organisational strengthening (OS) interventions CSSF partners; Activity=Familiarisation visits to CSSF II & III CSOs (January - March 2026) | V11: 1.1.1
C12: Support and facilitate the implementation of CSOs demand-based OS activities based on their approved OS plan and requests (ToRs) - When and as requested (4 times on average per organization '43' in 2026) -Using Service Providers | D12: Quarterly implementation of Demand OS | F12: Manager CSO Development | G12: 4 | H12: 1211250 | I12: =(G12*H12) -> 4845000 | J12: =I12/30 -> 161500 | K12: Q1, Q2,Q3&Q4 | L12: 807500 | M12: 1816875 | N12: 1816875 | O12: 403750 | P12: 5400 | Q12: Training & Learning | R12: 4000-015-007-010 | S12: Conduct 5 day capacity building training | T12: Comic Relief | U12: Funding Source=Comic Relief; Activity=Support and facilitate the implementation of CSOs demand-based OS activities based on their approved OS plan and requests (ToRs) - When and as requested (4 times on average per organization '43' in 2026) -Using Service Providers | V12: 1.1.2
C13: Conduct quality assurance and capacity strengthening visits to 38 CSSF partners and 17 CF Partners | D13: Quarterly Quality Assurance Visits | F13: Manager CSO Development | G13: 4 | H13: 514123.96 | I13: =(G13*H13) -> 2056495.8 | J13: =I13/30 -> 68549.861 | K13: Q1, Q2,Q3&Q4 | L13: 373908.33 | M13: =560862.5+186954.17 -> 747816.67 | N13: =560862.5+186954.17 -> 747816.67 | O13: 186954.17 | P13: 5400 | Q13: Training & Learning | R13: 4000-015-007-010 | S13: Conduct 5 day capacity building training | T13: Comic Relief | U13: Funding Source=Comic Relief; Activity=Conduct quality assurance and capacity strengthening visits to 38 CSSF partners and 17 CF Partners | V13: 1.1.2
C14: Quarterly review of 38 financial and narrative reports, respectively - CLD team | D14: Quarterly Review of Partners reports Communication costs | F14: Manager CSO Development | G14: 4 | H14: 1000 | I14: =G14*H14 -> 4000 | J14: =I14/30 -> 133.33333 | K14: Q1, Q2,Q3&Q4 | L14: =I14/4 -> 1000 | M14: 1000 | N14: 1000 | O14: 1000 | P14: 5400 | Q14: Training & Learning | R14: 4000-015-007-010 | S14: Conduct 5 day capacity building training | T14: Comic Relief | U14: Funding Source=Comic Relief; Activity=Quarterly review of 38 financial and narrative reports, respectively - CLD team | V14: 1.1.2
C15: Conduct biannual mandatory OS trainings: M&E, financial management, fraud and risk and safeguarding and ABCD training/ community engagement - 4 days Twice a year | D15: Bi-Annual a Year 4days mandatory OS trainings | F15: Manager CSO Development | G15: 2 | H15: 751762 | I15: =(G15*H15) -> 1503524 | J15: =I15/30 -> 50117.467 | K15: Q2 &Q3 | M15: =I15/2 -> 751762 | N15: 751762 | P15: 5400 | Q15: Training & Learning | R15: 4000-015-007-010 | S15: Conduct 5 day capacity building training | T15: Comic Relief | U15: Funding Source=Comic Relief; Activity=Conduct biannual mandatory OS trainings: M&E, financial management, fraud and risk and safeguarding and ABCD training/ community engagement - 4 days Twice a year; ProjCode=1.3.5 | V15: 1.1.2
A16: Supporting CSOS | B16: Objective 2: CF CSOs to access the After Care Support (ACS) Strengthening systems, and operalisation of catalyst fund partners. The grant will run for 12 months | C16: Support 17 CF CSO partners with tailor made activities responding to the OS prioritised plan - Aftercare Support Programme | D16: Quarterly After Care support trainings to 17 Catalyst Fund CSOs | E16: Capacity development | F16: Manager CSO Development | G16: 4 | H16: 372539.06 | I16: =(G16*H16) -> 1490156.2 | J16: =I16/30 -> 49671.875 | K16: Q1, Q2,Q3&Q4 | L16: 270937.5 | M16: 541875 | N16: 541875 | O16: 135468.75 | P16: 5400 | Q16: Training & Learning | R16: 4000-015-007-010 | S16: Conduct 5 day capacity building training | T16: Comic Relief | U16: Funding Source=Comic Relief; Strategic Pillar=Supporting CSOS; Programme Objective=Objective 2: CF CSOs to access the After Care Support (ACS) Strengthening systems, and operalisation of catalyst fund partners. The grant will run for 12 months; Activity=Support 17 CF CSO partners with tailor made activities responding to the OS prioritised plan - Aftercare Support Programme | V16: 1.2.2
C17: Conduct Biannual tailored OS support review and organizational needs assessment with 17 catalyst fund partners - 17 partners x 3 representatives x 4 days and 5 ZGF staff | D17: Conduct Biannual tailored OS support review and organizational assessment | F17: Manager CSO Development | G17: 2 | H17: 223238 | I17: =G17*H17 -> 446476 | J17: =I17/30 -> 14882.533 | K17: Q2 &Q4 | M17: =I17/2 -> 223238 | O17: 223238 | P17: 5400 | Q17: Training & Learning | R17: 4000-015-007-010 | S17: Conduct 5 day capacity building training | T17: Comic Relief | U17: Funding Source=Comic Relief; Activity=Conduct Biannual tailored OS support review and organizational needs assessment with 17 catalyst fund partners - 17 partners x 3 representatives x 4 days and 5 ZGF staff | V17: 1.2.2
A18: Supporting CSOS | B18: Objective 3: Selection of CSOs to access Community Resourcing Match Fund (CRMF) | C18: Launch of CRMF programme | D18: Launch of CRMF programme | E18: Grants & Contract Management | F18: Manager CSO Development | G18: 1 | H18: 500000 | I18: =G18*H18 -> 500000 | J18: =I18/30 -> 16666.667 | K18: Q4 | O18: =I18 -> 500000 | P18: 5100 | Q18: Grants & Capacity Strengthening | R18: 4000-010-004 | S18: Selection of CSOs to access Community Resourcing Match Fund (CRMF | T18: Comic Relief | U18: Funding Source=Comic Relief; Strategic Pillar=Supporting CSOS; Programme Objective=Objective 3: Selection of CSOs to access Community Resourcing Match Fund (CRMF); Activity=Launch of CRMF programme | V18: 1.3.1
A19: Supporting CSOS | B19: Objective 4: Organisational learning | C19: 1. ZGF Institutional OS | D19: OS Plan Activitites | E19: Capacity development | F19: Snr Specialist-Risk & Compliance | G19: 4 | H19: 550885 | I19: =G19*H19 -> 2203540 | J19: =I19/30 -> 73451.333 | K19: Q1, Q2,Q3&Q4 | L19: 367256.67 | M19: =550885+183628.33 -> 734513.33 | N19: =550885+367256.67 -> 918141.67 | O19: 183628.33 | P19: 5400 | Q19: Training & Learning | R19: 4000-015-007-010 | S19: Conduct capacity building training | T19: Comic Relief | U19: Funding Source=Comic Relief; Strategic Pillar=Supporting CSOS; Programme Objective=Objective 4: Organisational learning; Activity=1. ZGF Institutional OS; ProjCode=4.3 | V19: 1.4.2
P20: 5400 | Q20: Training & Learning | R20: 4000-015-007-010 | S20: Conduct capacity building training | T20: Comic Relief | V20: 1.4.2
C21: 2.2027 Planning & Budgeting - Fourth Quarter 2026 | D21: Annual review and workplanning activity | F21: HR & Admin Mgr | G21: 1 | H21: 669700 | I21: =G21*H21 -> 669700 | J21: =I21/30 -> 22323.333 | K21: Q4 | O21: =I21 -> 669700 | P21: 5400 | Q21: Training & Learning | R21: 4000-015-007-010 | S21: Conduct capacity building training | T21: Comic Relief | U21: Funding Source=Comic Relief; Activity=2.2027 Planning & Budgeting - Fourth Quarter 2026 | V21: 1.4.2
C22: Human Resource Related Os | J22: =I22/30 -> 0 | P22: 5400 | Q22: Training & Learning | R22: 4000-015-007-010 | S22: Conduct capacity building training | T22: Comic Relief | U22: Funding Source=Comic Relief; Activity=Human Resource Related Os | V22: 1.4.2
C23: 1.Team Building - First Quarter 2026 | D23: Team Build Activity | F23: HR & Admin Mgr | G23: 1 | H23: 287740 | I23: =G23*H23 -> 287740 | J23: =I23/30 -> 9591.3333 | K23: Q1 | L23: =I23 -> 287740 | P23: 5400 | Q23: Training & Learning | R23: 4000-015-007-010 | S23: Conduct capacity building training | T23: Comic Relief | U23: Funding Source=Comic Relief; Activity=1.Team Building - First Quarter 2026 | V23: 1.4.2
C24: 2.Other Employee Engagement Initiatives | D24: Quarterly Departmental Team build | F24: HR & Admin Mgr | G24: 4 | H24: 13000 | I24: =G24*H24 -> 52000 | J24: =I24/30 -> 1733.3333 | K24: Q1, Q2,Q3&Q4 | L24: =I24/4 -> 13000 | M24: 13000 | N24: 13000 | O24: 13000 | P24: 5400 | Q24: Training & Learning | R24: 4000-015-007-010 | S24: Community meetings - Refreshments | T24: Comic Relief | U24: Funding Source=Comic Relief; Activity=2.Other Employee Engagement Initiatives | V24: 1.4.2
C25: 3.Town Halls-Combine with Whole team socials | D25: Quarterly beginning Q2 | F25: HR & Admin Mgr | G25: 3 | H25: 16666.667 | I25: =G25*H25 -> 50000 | J25: =I25/30 -> 1666.6667 | K25: Q2,Q3&Q4 | M25: =I25/3 -> 16666.667 | N25: 16666.667 | O25: 16666.667 | P25: 5400 | Q25: Training & Learning | R25: 4000-015-007-010 | S25: Conduct capacity building training | T25: Comic Relief | U25: Funding Source=Comic Relief; Activity=3.Town Halls-Combine with Whole team socials | V25: 1.4.2
C26: 6.Employee Climate / Engagement Survey | D26: One Employee Engagement Survey | F26: HR & Admin Mgr | G26: 1 | H26: 60000 | I26: =G26*H26 -> 60000 | J26: =I26/30 -> 2000 | K26: Q2 | M26: =I26 -> 60000 | P26: 5200 | Q26: Community Engagement & Field Work | R26: 4000-015-007-010 | S26: Community meetings - Refreshments | T26: Comic Relief | U26: Funding Source=Comic Relief; Activity=6.Employee Climate / Engagement Survey | V26: 1.4.3
C27: 7.Leadership Assessment | D27: Leadership Assessment | F27: HR & Admin Mgr | G27: 1 | H27: 50000 | I27: =G27*H27 -> 50000 | J27: =I27/30 -> 1666.6667 | K27: Q2 | M27: =I27 -> 50000 | P27: 5400 | Q27: Training & Learning | R27: 4000-015-007-010 | S27: Conduct capacity building training | T27: Comic Relief | U27: Funding Source=Comic Relief; Activity=7.Leadership Assessment | V27: 1.4.2
C28: 8.IDP Interventions | D28: IDP interventions from Performance Contracts | F28: HR & Admin Mgr | G28: 4 | H28: 25000 | I28: =G28*H28 -> 100000 | J28: =I28/30 -> 3333.3333 | K28: Q3 | N28: =I28 -> 100000 | P28: 5400 | Q28: Training & Learning | R28: 4000-015-007-010 | S28: Conduct capacity building training | T28: Comic Relief | U28: Funding Source=Comic Relief; Activity=8.IDP Interventions | V28: 1.4.2
C29: Organisational management | I29: =G29*H29 -> 0 | J29: =I29/30 -> 0 | P29: 5400 | Q29: Training & Learning | R29: 4000-015-007-010 | S29: Conduct capacity building training | T29: Comic Relief | U29: Funding Source=Comic Relief; Activity=Organisational management; ZGFCode=5.1.1 | V29: 1.4.2
C30: 1. Board oversight | D30: Five Board Meetings(45units) , Six Committee meetings(F&A), Five-A&R, Four(Strategy & Resource, Grants Committees) and Two Nominations Committee | E30: Organisational governance | F30: CEO | G30: 129 | H30: 3500 | I30: =G30*H30 -> 451500 | J30: =I30/30 -> 15050 | K30: Q1, Q2,Q3&Q4 | L30: =I30/4 -> 112875 | M30: 112875 | N30: 112875 | O30: 112875 | P30: 5800 | Q30: Operations & Governance | R30: 4000-015-007-010 | S30: Board oversight/governance | T30: Comic Relief | U30: Funding Source=Comic Relief; Activity=1. Board oversight; ZGFCode=5.1.1 | V30: 1.4.4
C31: 2. Audits | D31: Institutional External Audits | F31: HoF | G31: 1 | H31: 215000 | I31: =G31*H31 -> 215000 | J31: =I31/30 -> 7166.6667 | K31: Q1&Q2 | L31: =I31/2 -> 107500 | M31: 107500 | P31: 5600 | Q31: Consultancy & Professional Services | R31: 4300-040-060-255 | S31: Commission external audit | T31: Comic Relief | U31: Funding Source=Comic Relief; Activity=2. Audits | V31: 1.4.6
A32: Supporting CSOS | B32: Objective 5: MERL | C32: Learning and Convening Events | D32: At least 4 learning and convening events | E32: Capacity development | F32: Manager CSO & Snr Specialist-MEAL | G32: 2 | H32: 639540 | I32: =G32*H32 -> 1279080 | J32: =I32/30 -> 42636 | K32: Q2&Q4 | M32: =I32/2 -> 639540 | O32: 639540 | P32: 5100 | Q32: Grants & Capacity Strengthening | R32: 4000-010-004 | S32: MERL | T32: Comic Relief | U32: Funding Source=Comic Relief; Strategic Pillar=Supporting CSOS; Programme Objective=Objective 5: MERL; Activity=Learning and Convening Events | V32: 1.5.1
C33: Hold annual OS review meetings with consultants _ Qtr 4- one day, 10 consultants | D33: Annual review with Service providers | F33: Snr Specialist-MEAL & Specialist CB | G33: 1 | H33: 59050 | I33: =G33*H33 -> 59050 | J33: =I33/30 -> 1968.3333 | K33: Q3 | N33: =I33 -> 59050 | P33: 5100 | Q33: Grants & Capacity Strengthening | R33: 4000-010-004 | S33: MERL | T33: Comic Relief | U33: Funding Source=Comic Relief; Activity=Hold annual OS review meetings with consultants _ Qtr 4- one day, 10 consultantsProjCode=3.5 | V33: 1.5.1
A34: Supporting CSOS | C34: Conduct Six(6) M&E visits to CSO partners | D34: Six M&E Visits(May , June July, Oct, Nov & Dec) | E34: Grants & Contract Management | F34: Snr Specialist-MEAL | G34: 6 | H34: 104200 | I34: =G34*H34 -> 625200 | J34: =I34/30 -> 20840 | K34: Q2,Q3&Q4 | M34: =I34/3 -> 208400 | N34: 208400 | O34: 208400 | P34: 5100 | Q34: Grants & Capacity Strengthening | R34: 4000-010-004 | S34: Disbursements to Grant Partners | T34: Comic Relief | U34: Funding Source=Comic Relief; Strategic Pillar=Supporting CSOS; Activity=Conduct Six(6) M&E visits to CSO partnersProjCode=4.2.2; ZGFCode=1.2 | V34: 1.5.1
C35: Out come harvest related activities | G35: 6 | H35: 61143.333 | I35: =G35*H35 -> 366860 | J35: =I35/30 -> 12228.667 | M35: =I35/3 -> 122286.67 | N35: 122286.67 | O35: 122286.67 | P35: 5100 | Q35: Grants & Capacity Strengthening | R35: 4000-010-004 | S35: Disbursements to Grant Partners | T35: Comic Relief | U35: Funding Source=Comic Relief; Activity=Out come harvest related activities; ProjCode=4.2; ZGFCode=1.2 | V35: 1.5.1
C36: Facilitate Programme Advisory Board meetings - 2 meeting in a year | D36: Two PAP meetings(7members) | G36: =2*7 -> 14 | H36: 2000 | I36: =G36*H36 -> 28000 | J36: =I36/30 -> 933.33333 | K36: Q2&Q4 | M36: =I36/2 -> 14000 | O36: 14000 | P36: 5100 | Q36: Grants & Capacity Strengthening | R36: 4000-010-004 | S36: Disbursements to Grant Partners | T36: Comic Relief | U36: Funding Source=Comic Relief; Activity=Facilitate Programme Advisory Board meetings - 2 meeting in a yearProjCode=4.2.8; ZGFCode=1.2 | V36: 1.5.1
A37: Supporting CSOS | C37: Development of M&E model and approaches | D37: Staff time input & stationery | E37: Grants & Contract Management | F37: Snr Specialist-MEAL | G37: 1 | H37: 1200 | I37: =G37*H37 -> 1200 | J37: =I37/30 -> 40 | K37: Q2 & Q3 | M37: =I37/2 -> 600 | N37: 600 | P37: 5100 | Q37: Grants & Capacity Strengthening | R37: 4000-010-004 | S37: MERL | T37: Comic Relief | U37: Funding Source=Comic Relief; Strategic Pillar=Supporting CSOS; Activity=Development of M&E model and approachesProjCode=1.3.1; ZGFCode=1.2 | V37: 1.5.1
A38: Building the field of community philanthropy | B38: Objective 6: To champion local philanthropy and diversified funding sources that promote community-led development in Zambia | C38: Dissemination of the Mapping of Philanthropy Actors Study | D38: Information Dissemination Workshop | E38: Promoting community philanthropy | F38: Manager Philanthropy | G38: 1 | H38: 59100 | I38: =G38*H38 -> 59100 | J38: =I38/30 -> 1970 | K38: Q3 | N38: =I38 -> 59100 | P38: 5300 | Q38: Philanthropy, Communications & Visibility | R38: 4200-035-050 | S38: Run advocacy campaign for philanthropic giving | T38: Comic Relief | U38: Funding Source=Comic Relief; Strategic Pillar=Building the field of community philanthropy; Programme Objective=Objective 6: To champion local philanthropy and diversified funding sources that promote community-led development in Zambia; Activity=Dissemination of the Mapping of Philanthropy Actors Study | V38: 3.6.5
C39: Country data collection and compiling input into the World Giving Report | D39: Data Collection Exercise | E39: Research | F39: Manager Philanthropy & Snr Specialist-MEAL | G39: 1 | H39: 50000 | I39: =G39*H39 -> 50000 | J39: =I39/30 -> 1666.6667 | K39: Q2 | M39: =I39 -> 50000 | P39: 5300 | Q39: Philanthropy, Communications & Visibility | R39: 4200-035-050 | S39: Run advocacy campaign for philanthropic giving | T39: Comic Relief | U39: Funding Source=Comic Relief; Activity=Country data collection and compiling input into the World Giving Report | V39: 3.6.5
C40: Establishing the Zambia Philanthropy Network - mapping, database, 2 meetings in 2026. | D40: Zambia Philanthropy Network | E40: Promoting community philanthropy | F40: Manager Philanthropy | G40: 1 | H40: 50000 | I40: =G40*H40 -> 50000 | J40: =I40/30 -> 1666.6667 | K40: Q3 | N40: =I40 -> 50000 | P40: 5300 | Q40: Philanthropy, Communications & Visibility | R40: 4200-035-050 | S40: Run advocacy campaign for philanthropic giving | T40: Comic Relief | U40: Funding Source=Comic Relief; Activity=Establishing the Zambia Philanthropy Network - mapping, database, 2 meetings in 2026. | V40: 3.6.5
A41: Building the field of community philanthropy | C41: Mapping existing CSOs in Eastern, Central, and Southern provinces (Including purchasing of tablets) - engage local data collectors (4) | D41: CSO Mapping Exercise-Feb, Mar&Apr | E41: Research - CSOs | F41: Manager CSO & Snr Specialist-MEAL | G41: 3 | H41: 73583.33 | I41: =G41*H41 -> 220749.99 | J41: =I41/30 -> 7358.333 | K41: Q1&Q2 | L41: =I41/2 -> 110374.99 | M41: 110374.99 | P41: 5300 | Q41: Philanthropy, Communications & Visibility | R41: 4200-035-050 | S41: Run advocacy campaign for philanthropic giving | T41: Comic Relief | U41: Funding Source=Comic Relief; Strategic Pillar=Building the field of community philanthropy; Activity=Mapping existing CSOs in Eastern, Central, and Southern provinces (Including purchasing of tablets) - engage local data collectors (4) | V41: 3.6.5
...

Sheet MOTTIII
A2: Zambian Governance Foundation Ltd.
A3: Mott Foundation - 2026 Annual work plan budget
A4: 1 January to 30 September 2026
A5: Name of project:Supporting the development of community foundations in Zambia | L5: Budget Distribution Per Quarter
A6: Strategic Pillar | B6: Objective | C6: Activities | D6: Output/Indicator | E6: Category | F6: Activity Owner | G6: Quantity | H6: Unit Cost | I6: Total Budget-ZMW | J6: Total Budget-USD | K6: Implementing Timeline | L6: Quarter1 | M6: Quarter2 | N6: Quarter3 | O6: Odoo Code | P6: Odoo Category | Q6: Legacy Suggested Code | R6: Legacy Suggested Description | S6: Funding Source | T6: Analytic Tags | U6: ZGF Code
A7: Strengthening Communities | B7: Objective 1.Community Foundation's community inclusion and Participation | C7: Hold meetings to discuss CFs inclusion of youth, women, PWD | D7: 1 training-Luangwa, 1 training- Rufunsa & Chisamba 1training -Chibombo | E7: Promoting community-led development | F7: Manager CLD | G7: 3 | H7: 33757 | I7: =G7*H7 -> 101271 | J7: =I7/25 -> 4050.84 | K7: Q1 | L7: =I7 -> 101271 | O7: 5800 | P7: Community Engagement & Field Work | Q7: 4300-050-090-325 | R7: Overhead costs | S7: MOTTIII | T7: Funding Source=MOTTIII; Strategic Pillar=Strengthening Communities; Programme Objective=Objective 1.Community Foundation's community inclusion and Participation; Activity=Hold meetings to discuss CFs inclusion of youth, women, PWD | U7: 2.1.3
A8: Strengthening Communities | B8: Objective 2.Facilitate establisment of 2 new community foundations | C8: Introduce concepts of community-led development and community foundation ( 2 communities x1 day) | D8: Targeted 2 communities Mpuka and Mukonka in Luangwa | E8: Promoting community-led development | F8: Manager CLD | G8: 2 | H8: 14034 | I8: =G8*H8 -> 28068 | J8: =I8/25 -> 1122.72 | K8: Q1 | L8: =I8 -> 28068 | O8: 5200 | P8: Community Engagement & Field Work | Q8: 4200-030-100-370 | R8: Community meetings - Refreshments | S8: MOTTIII | T8: Funding Source=MOTTIII; Strategic Pillar=Strengthening Communities; Programme Objective=Objective 2.Facilitate establisment of 2 new community foundations; Activity=Introduce concepts of community-led development and community foundation ( 2 communities x1 day) | U8: 2.2.3
C9: Introduction to by laws, articles of incorporation | D9: Targeted 2 communities Mpuka and Mukonka in Luangwa | E9: Promoting community-led development | F9: Manager CLD | G9: 2 | H9: 18094 | I9: =G9*H9 -> 36188 | J9: =I9/25 -> 1447.52 | K9: Q1 | L9: =I9 -> 36188 | O9: 5800 | P9: Community Engagement & Field Work | Q9: 4300-050-090-325 | R9: Overhead costs | S9: MOTTIII | T9: Funding Source=MOTTIII; Activity=Introduction to by laws, articles of incorporation | U9: 2.2.3
C10: Facilitate consensus building meetings for registration of community foundations and asset mapping exercise for 2 communities (2x1x40 people) | D10: Targeted 2 communities Mpuka and Mukonka in Luangwa | E10: Promoting community-led development | F10: Manager CLD | G10: 2 | H10: 24109 | I10: =G10*H10 -> 48218 | J10: =I10/25 -> 1928.72 | K10: Q1 | L10: =I10 -> 48218 | O10: 5200 | P10: Community Engagement & Field Work | Q10: 4200-030-100-370 | R10: Community meetings - Refreshments | S10: MOTTIII | T10: Funding Source=MOTTIII; Activity=Facilitate consensus building meetings for registration of community foundations and asset mapping exercise for 2 communities (2x1x40 people) | U10: 2.2.3
C11: Develop a community profile (2x1dayx30 pp lunch) | D11: Targeted 2 communities Mpuka and Mukonka in Luangwa | E11: Promoting community-led development | F11: Manager CLD | G11: 2 | H11: 9734 | I11: =G11*H11 -> 19468 | J11: =I11/25 -> 778.72 | K11: Q1 | L11: =I11 -> 19468 | O11: 5200 | P11: Community Engagement & Field Work | Q11: 4200-030-100-370 | R11: Community meetings - Refreshments | S11: MOTTIII | T11: Funding Source=MOTTIII; Activity=Develop a community profile (2x1dayx30 pp lunch) | U11: 2.2.3
C12: Conduct business and entrepreneurship training and community project identification exercise (2x5daysx30 pp lunch) | D12: New CFs Mpuka and Mukonka Communities in Luangwa | E12: Participatory grant making | F12: Manager CLD | G12: 2 | H12: 16694 | I12: =G12*H12 -> 33388 | J12: =I12/25 -> 1335.52 | K12: Q1 | L12: =I12 -> 33388 | O12: 5400 | P12: Training & Learning | Q12: 4000-015-007-010 | R12: Conduct 5 day capacity building training | S12: MOTTIII | T12: Funding Source=MOTTIII; Activity=Conduct business and entrepreneurship training and community project identification exercise (2x5daysx30 pp lunch); ProjCode=1.2.6 | U12: 2.2.2
C13: Conduct environmental studies (2x1 day x 30 pp lunch) | D13: Train Mpuka and Mukonka Communities in Luangwa | E13: Promoting community-led development | F13: Manager CLD | G13: 2 | H13: 10734 | I13: =G13*H13 -> 21468 | J13: =I13/25 -> 858.72 | K13: Q1 | L13: =I13 -> 21468 | O13: 5800 | P13: Community Engagement & Field Work | Q13: 4300-050-090-325 | R13: Overhead costs | S13: MOTTIII | T13: Funding Source=MOTTIII; Activity=Conduct environmental studies (2x1 day x 30 pp lunch); ProjCode=2.6; ZGFCode=2.1 | U13: 2.2.3
C14: Conduct peer review for action plans, budget and business plans (2x1dayx35 pp lunch; 8 transport refunds and full per diems for CFs) | D14: Mpuka and Mukonka Communities in Luangwa-Participatory grant making process | E14: Grants and contract management | F14: Manager CLD | G14: 2 | H14: 19369 | I14: =G14*H14 -> 38738 | J14: =I14/25 -> 1549.52 | K14: Q1 | L14: =I14 -> 38738 | O14: 5500 | P14: Community Engagement & Field Work | Q14: 4200-030-022-360 | R14: Conduct community trainings - Fuel | S14: MOTTIII | T14: Funding Source=MOTTIII; Activity=Conduct peer review for action plans, budget and business plans (2x1dayx35 pp lunch; 8 transport refunds and full per diems for CFs); ProjCode=3.5 | U14: 2.2.3
C15: Conduct peer review for action plans, budget and business plans (2x1dayx35 pp lunch; 8 transport refunds and full per diems for CFs) | D15: Mpuka and Mukonka Communities in Luangwa-Participatory grant making process | E15: Grants and contract management | F15: Manager CLD | G15: 2 | H15: 23954 | I15: =G15*H15 -> 47908 | J15: =I15/25 -> 1916.32 | K15: Q1 | L15: =I15 -> 47908 | O15: 5500 | P15: Community Engagement & Field Work | Q15: 4200-030-022-360 | R15: Conduct community trainings - Fuel | S15: MOTTIII | T15: Funding Source=MOTTIII; Activity=Conduct peer review for action plans, budget and business plans (2x1dayx35 pp lunch; 8 transport refunds and full per diems for CFs); ProjCode=3.5 | U15: 2.2.3
C16: Submission of business plans and budgets to the grants committee (Grants committee members fees for 1 day) | D16: Grants Committee review of Mpuka and Mukonka Communities in Luangwa-Participatory grant making process | E16: Grants and contract management | F16: Manager CLD | G16: 4 | H16: 3500 | I16: =G16*H16 -> 14000 | J16: =I16/25 -> 560 | K16: Q1 | L16: =I16 -> 14000 | O16: 5100 | P16: Grants & Capacity Strengthening | Q16: 4000-010-004 | R16: Disbursements to Grant Partners | S16: MOTTIII | T16: Funding Source=MOTTIII; Activity=Submission of business plans and budgets to the grants committee (Grants committee members fees for 1 day); ProjCode=5.3; ZGFCode=2.3 | U16: 2.2.1
C17: Grants and programmes orientation 2 x 1 day per CF x 5 people per org | D17: Orient Kankole, Mpuka and Mukonka Communities in Luangwa | E17: Grants and contract management | F17: Manager CLD | G17: 2 | H17: 14519 | I17: =G17*H17 -> 29038 | J17: =I17/25 -> 1161.52 | K17: Q1 | L17: =I17 -> 29038 | O17: 5100 | P17: Grants & Capacity Strengthening | Q17: 4000-010-004 | R17: Disbursements to Grant Partners | S17: MOTTIII | T17: Funding Source=MOTTIII; Activity=Grants and programmes orientation 2 x 1 day per CF x 5 people per org | U17: 2.2.1
C18: Grants disbursment | D18: Matching grant disbursements Kankole, Mpuka and Mukonka Communities in Luangwa | E18: Grants and contract management | F18: Manager CLD | G18: 3 | H18: 60000 | I18: =G18*H18 -> 180000 | J18: =I18/25 -> 7200 | K18: Q1 | L18: =I18 -> 180000 | O18: 5100 | P18: Grants & Capacity Strengthening | Q18: 4000-010-004 | R18: Disbursements to Grant Partners | S18: MOTTIII | T18: Funding Source=MOTTIII; Activity=Grants disbursment | U18: 2.2.1
A19: Strengthening Communities | B19: Objective 3. Close-out of Mott III | C19: Conduct Close-out exercise (9CFs X 4 staff X 3 days) | D19: Mott3 close out Exercise with CFs | E19: Grants and contract management | F19: Manager CLD | G19: 1 | H19: 120518 | I19: =G19*H19 -> 120518 | J19: =I19/25 -> 4820.72 | K19: Q3 | N19: =I19 -> 120518 | O19: 5700 | P19: Staff Costs | Q19: 4300-050-090-320 | R19: Staff input | S19: MOTTIII | T19: Funding Source=MOTTIII; Strategic Pillar=Strengthening Communities; Programme Objective=Objective 3. Close-out of Mott III; Activity=Conduct Close-out exercise (9CFs X 4 staff X 3 days) | U19: 2.3.4
A20: Strengthening Communities | B20: Objective 4. Explore registration of CFs as Trusts | C20: Engage community foundation on registration as Trust | D20: Engage CF's in Luangwa, Rufunsa and Chibombo | E20: Promoting community-led development | F20: Manager CLD | G20: 1 | H20: 61238 | I20: =G20*H20 -> 61238 | J20: =I20/25 -> 2449.52 | K20: Q2 | M20: =I20 -> 61238 | O20: 5200 | P20: Community Engagement & Field Work | Q20: 4200-030-100-370 | R20: Community meetings - Refreshments | S20: MOTTIII | T20: Funding Source=MOTTIII; Strategic Pillar=Strengthening Communities; Programme Objective=Objective 4. Explore registration of CFs as Trusts; Activity=Engage community foundation on registration as Trust | U20: 2.4.3
A21: Strengthening Communities | B21: Objective 5.Strengthen CFs governance structures and capacity ( 11 community Foundations) | C21: Conduct CFs Leadership and Governance training (11 CFs x3daysx20 pp in Luangwa, Rufunsa & Chibombo) | D21: Train 11 CF's in Luangwa, Rufunsa and Chibombo | E21: Supporting demand based capacity development | F21: Manager CLD | G21: 3 | H21: 43094 | I21: =G21*H21 -> 129282 | J21: =I21/25 -> 5171.28 | K21: Q1 | L21: =I21 -> 129282 | O21: 5400 | P21: Grants & Capacity Strengthening | Q21: 4000-015-007-010 | R21: Conduct 5 day capacity building training | S21: MOTTIII | T21: Funding Source=MOTTIII; Strategic Pillar=Strengthening Communities; Programme Objective=Objective 5.Strengthen CFs governance structures and capacity ( 11 community Foundations); Activity=Conduct CFs Leadership and Governance training (11 CFs x3daysx20 pp in Luangwa, Rufunsa & Chibombo); ProjCode=4.1.4 | U21: 2.5.1
C22: Train 11CFs committees in various functions-in Luangwa, Rufunsa & Chibombo | D22: Train 11 CF's in Luangwa, Rufunsa and Chibombo | E22: Supporting demand based capacity development | F22: Manager CLD | G22: 3 | H22: 38909.333 | I22: =G22*H22 -> 116728 | J22: =I22/25 -> 4669.12 | K22: Q2 | M22: =I22 -> 116728 | O22: 5800 | P22: Grants & Capacity Strengthening | Q22: 4300-050-090-325 | R22: Overhead costs | S22: MOTTIII | T22: Funding Source=MOTTIII; Activity=Train 11CFs committees in various functions-in Luangwa, Rufunsa & Chibombo | U22: 2.5.1
C23: Support resource mobilization efforts at community level-in Luangwa, Rufunsa & Chibombo | D23: Support the 11 CF's in Luangwa, Rufunsa and Chibombo | E23: Supporting community financial asset building | F23: Manager CLD | G23: 3 | H23: 22536 | I23: =G23*H23 -> 67608 | J23: =I23/25 -> 2704.32 | K23: Q1 | L23: =I23 -> 67608 | O23: 5200 | P23: Grants & Capacity Strengthening | Q23: 4200-030-100-370 | R23: Community meetings - Refreshments | S23: MOTTIII | T23: Funding Source=MOTTIII; Activity=Support resource mobilization efforts at community level-in Luangwa, Rufunsa & Chibombo | U23: 2.5.1
A24: Building the Field of Community Philanthropy | B24: Objective 6.Establishment of CF community fund | C24: Initiate establishment of CF's community fund -Staff time | D24: Support 11 CF's in Luangwa, Rufunsa and Chibombo to setup a community fund | E24: Supporting community financial asset building | F24: Manager CLD | I24: =G24*H24 -> 0 | J24: =I24/25 -> 0 | K24: Q1&Q2 | L24: =I24/2 -> 0 | M24: =I24/2 -> 0 | O24: 5200 | P24: Community Engagement & Field Work | Q24: 4200-030-100-370 | R24: Community meetings - Refreshments | S24: MOTTIII | T24: Funding Source=MOTTIII; Strategic Pillar=Building the Field of Community Philanthropy; Programme Objective=Objective 6.Establishment of CF community fund; Activity=Initiate establishment of CF's community fund -Staff time; ProjCode=2 | U24: 2.6.3
A25: Strengthening Communities | B25: Objective 7.Mott 2026-2028 Brainstorming: Repositioning Community Foundation Model | C25: Conduct field visit to 3 Districts | D25: Repositioning the CF model | E25: Promoting community-led development | F25: Manager CLD | G25: 3 | H25: 22636 | I25: =G25*H25 -> 67908 | J25: =I25/25 -> 2716.32 | K25: Q2 | M25: =I25 -> 67908 | O25: 5800 | P25: Training & Learning | Q25: 4300-050-090-325 | R25: Overhead costs | S25: MOTTIII | T25: Funding Source=MOTTIII; Strategic Pillar=Strengthening Communities; Programme Objective=Objective 7.Mott 2026-2028 Brainstorming: Repositioning Community Foundation Model; Activity=Conduct field visit to 3 Districts | U25: 2.7.2
A26: Strengthening Communities | B26: Objective 8.Facilitate networking of sustainable agriculture (agroecology) | C26: Conduct training in climate change adaptation and land management (FMNR) in 3 Districts | D26: Train 11 CF's in Luangwa, Rufunsa and Chibombo | E26: Capacity development | F26: Manager CLD | G26: 3 | H26: 23402.667 | I26: =G26*H26 -> 70208 | J26: =I26/25 -> 2808.32 | K26: Q2 | M26: =I26 -> 70208 | O26: 5400 | P26: Training & Learning | Q26: 4000-015-007-010 | R26: Conduct 5 day capacity building training | S26: MOTTIII | T26: Funding Source=MOTTIII; Strategic Pillar=Strengthening Communities; Programme Objective=Objective 8.Facilitate networking of sustainable agriculture (agroecology); Activity=Conduct training in climate change adaptation and land management (FMNR) in 3 Districts | U26: 2.8.2
A27: Strengthening Communities | B27: Objective 9.Offer Cfs support in various aspects of financial asset building | C27: Offer CFs support in various aspects of financial asset building in 3 Districts | D27: Support 11 CF's in Luangwa, Rufunsa and Chibombo | E27: Supporting community financial asset building | F27: Manager CLD | G27: 3 | H27: 24509.333 | I27: =G27*H27 -> 73528 | J27: =I27/25 -> 2941.12 | K27: Q1,Q2&Q3 | L27: =I27/3 -> 24509.333 | M27: =I27/3 -> 24509.333 | N27: =I27/3 -> 24509.333 | O27: 5800 | P27: Grants & Capacity Strengthening | Q27: 4300-050-090-325 | R27: Overhead costs | S27: MOTTIII | T27: Funding Source=MOTTIII; Strategic Pillar=Strengthening Communities; Programme Objective=Objective 9.Offer Cfs support in various aspects of financial asset building; Activity=Offer CFs support in various aspects of financial asset building in 3 Districts; ProjCode=6 | U27: 2.9.1
B28: Objective 10.0 Staff development | C28: Explore registration with CAPSI Conduct funding proposals development training for staff | D28: ZGF staff development | E28: Capacity development | F28: Manager CLD | I28: =G28*H28 -> 0 | J28: =I28/25 -> 0 | K28: Q1 | L28: =I28 -> 0 | O28: 5400 | P28: Training & Learning | Q28: 4000-015-007-010 | R28: Conduct 5 day capacity building training | S28: MOTTIII | T28: Funding Source=MOTTIII; Programme Objective=Objective 10.0 Staff development; Activity=Explore registration with CAPSI Conduct funding proposals development training for staff | U28: 2.10.2
A29: Strengthening Communities | B29: Objective 11.0 M&E | C29: Grants M&E Visits | D29: Grant M&E activities | E29: Grants and contract management | F29: Snr Specialist MEAL | G29: 3 | H29: 46987.667 | I29: =G29*H29 -> 140963 | J29: =I29/25 -> 5638.52 | K29: Q1,Q2&Q3 | L29: =I29/3 -> 46987.667 | M29: =I29/3 -> 46987.667 | N29: =I29/3 -> 46987.667 | O29: 5100 | P29: Grants & Capacity Strengthening | Q29: 4000-010-004 | R29: Disbursements to Grant Partners | S29: MOTTIII | T29: Funding Source=MOTTIII; Strategic Pillar=Strengthening Communities; Programme Objective=Objective 11.0 M&E; Activity=Grants M&E Visits | U29: 2.11.1
A30: Strengthening Communities | B30: Objective 12.0 Communications and Networking | C30: Support the launch of CF'S Strategic Plans (1 launch) | D30: Launching of CFs strategies | E30: Promoting community-led development | F30: Specialist-Comms & Advocacy | G30: 1 | H30: 137450 | I30: =G30*H30 -> 137450 | J30: =I30/25 -> 5498 | K30: Q1 | L30: =I30 -> 137450 | O30: 5800 | P30: Community Engagement & Field Work | Q30: 4300-050-090-325 | R30: Overhead costs | S30: MOTTIII | T30: Funding Source=MOTTIII; Strategic Pillar=Strengthening Communities; Programme Objective=Objective 12.0 Communications and Networking; Activity=Support the launch of CF'S Strategic Plans (1 launch) | U30: 2.12.3
A31: Building the Field of Community Philanthropy | C31: Media and CSO partners familiarisation trip to two communities | D31: One trip to 2 communities | E31: Promoting community-led development | F31: Specialist-Comms & Advocacy | G31: 1 | H31: 31580 | I31: =G31*H31 -> 31580 | J31: =I31/25 -> 1263.2 | K31: Q2 | M31: =I31 -> 31580 | O31: 5300 | P31: Community Engagement & Field Work | Q31: 4200-035-050 | R31: Run advocacy campaign for philanthropic giving | S31: MOTTIII | T31: Funding Source=MOTTIII; Strategic Pillar=Building the Field of Community Philanthropy; Activity=Media and CSO partners familiarisation trip to two communities | U31: 3.12.3
C32: Courtesy call to ministry of local government | D32: Courtesy call to ministry of local government | E32: Networking and partnership building | F32: Specialist-Comms & Advocacy | G32: 1 | H32: 3340 | I32: =G32*H32 -> 3340 | J32: =I32/25 -> 133.6 | K32: Q2 | M32: =I32 -> 3340 | O32: 5800 | P32: Philanthropy, Communications & Visibility | Q32: 4300-050-090-325 | R32: Overhead costs | S32: MOTTIII | T32: Funding Source=MOTTIII; Activity=Courtesy call to ministry of local government | U32: 3.12.5
C33: CF Documentaries | D33: 1 CF Documentary | E33: Networking and partnership building | F33: Specialist-Comms & Advocacy | G33: 1 | H33: 63660 | I33: =G33*H33 -> 63660 | J33: =I33/25 -> 2546.4 | K33: Q1 | L33: =I33 -> 63660 | O33: 5800 | P33: Philanthropy, Communications & Visibility | Q33: 4300-050-090-325 | R33: Overhead costs | S33: MOTTIII | T33: Funding Source=MOTTIII; Activity=CF Documentaries; ProjCode=13.2 | U33: 3.12.5
C34: Regional Conferences | D34: Participation in Community Foundations regional | E34: Networking and partnership building | F34: Manager CLD | G34: 1 | H34: 200000 | I34: =G34*H34 -> 200000 | J34: =I34/25 -> 8000 | K34: Q2 | M34: =I34 -> 200000 | O34: 5800 | P34: Philanthropy, Communications & Visibility | Q34: 4300-050-090-325 | R34: Overhead costs | S34: MOTTIII | T34: Funding Source=MOTTIII; Activity=Regional Conferences | U34: 3.12.5
C35: CSO Fair | D35: CSO Fair: Strengthening community resilience through locally-led initiatives | E35: Promoting community philanthropy | F35: Specialist-Comms & Advocacy | G35: 1 | H35: 169600 | I35: =G35*H35 -> 169600 | J35: =I35/25 -> 6784 | K35: Q1 | L35: =I35 -> 169600 | O35: 5500 | P35: Community Engagement & Field Work | Q35: 4200-030-022-360 | R35: Conduct community trainings - Fuel | S35: MOTTIII | T35: Funding Source=MOTTIII; Activity=CSO Fair; ProjCode=13.1; ZGFCode=3.2 | U35: 3.12.3
C36: Radio and TV programmes dicussing CF and CLD | D36: Radio and TV programmes dicussing CF and CLD | E36: Promoting community philanthropy | G36: 1 | H36: 30000 | I36: =G36*H36 -> 30000 | J36: =I36/25 -> 1200 | K36: Q1&Q3 | L36: =I36/2 -> 15000 | N36: =I36/2 -> 15000 | O36: 5300 | P36: Philanthropy, Communications & Visibility | Q36: 4200-035-050 | R36: Run advocacy campaign for philanthropic giving | S36: MOTTIII | T36: Funding Source=MOTTIII; Activity=Radio and TV programmes dicussing CF and CLD | U36: 3.12.5
A37: Operations | B37: Objective 13: Operational / running costs | C37: Staff Time Charges | D37: Monthly Staff Cost | E37: Operational running costs | F37: HoF | G37: 9 | H37: 131666 | I37: =G37*H37 -> 1184994 | J37: =I37/25 -> 47399.76 | K37: Q1,Q2&Q3 | L37: =I37/3 -> 394998 | M37: =I37/3 -> 394998 | N37: =I37/3 -> 394998 | O37: 5700 | P37: Staff Costs | Q37: 4300-050-090-320 | R37: Staff input | S37: MOTTIII | T37: Funding Source=MOTTIII; Strategic Pillar=Operations; Programme Objective=Operational / running costs; Activity=Staff Time Charges | U37: 4.13.4
C38: Overheads | D38: Monthly Indirect Costs(Overheads) | E38: Operational running costs | F38: HoF | G38: 9 | H38: 26500 | I38: =G38*H38 -> 238500 | J38: =I38/25 -> 9540 | K38: Q1,Q2&Q4 | L38: =I38/3 -> 79500 | M38: =I38/3 -> 79500 | N38: =I38/3 -> 79500 | O38: 5800 | P38: Operations / Running Costs | Q38: 4300-050-090-325 | R38: Overhead costs | S38: MOTTIII | T38: Funding Source=MOTTIII; Activity=Overheads; ZGFCode=5.3.1.2 | U38: 4.13.4
A39: TOTAL BUDGET | B39: TOTAL BUDGET | I39: =SUM(I6:I38) -> 3504858 | J39: =SUM(J6:J38) -> 140194.32 | L39: =SUM(L6:L38) -> 1726348 | M39: =SUM(M6:M38) -> 1096997 | N39: =SUM(N6:N38) -> 681513 | O39: 5800 | P39: Operations / Running Costs | Q39: 4300-050-090-325 | R39: Overhead costs | S39: MOTTIII | T39: Funding Source=MOTTIII; Strategic Pillar=TOTAL BUDGET; Programme Objective=TOTAL BUDGET

Sheet KaluluII
A1: Zambian Governance Foundation Ltd.
A2: Kalulu - 2026 Annual work plan budget
A3: 1 January to 31 December 2026
A4: Name of project:Community-led development through youth-led entrepreneurship
A6: Strategic Pillar | B6: Objective | C6: Activities | D6: Output/Indicator | E6: Category | F6: Activity Owner | G6: Quantity | H6: Unit Cost | I6: Total Budget-ZMW | J6: Total Budget-USD | K6: Implementing Timeline | L6: Quarter1 | M6: Quarter2 | N6: Quarter3 | O6: Quarter4 | P6: Odoo Code | Q6: Odoo Category | R6: Legacy Suggested Code | S6: Legacy Suggested Description | T6: Funding Source | U6: Analytic Tags | V6: ZGF Code
A7: Strengthening Communities | B7: Objective 1: Promote the establishment of youth-led businesses and cooperatives, with a special focus on out of school adolescent girls and young women | C7: Facilitate project identification and action planning in each community | D7: Business proposals and action plans -3 Communities(Chipata, Mandevu,Chawama) | E7: Participatory grant making | F7: Manager CLD | G7: 3 | H7: 7893.33 | I7: =G7*H7 -> 23679.99 | J7: =I7/25 -> 947.1996 | K7: Q1 | L7: =I7 -> 23679.99 | P7: 5200 | Q7: Community Engagement & Field Work | R7: 4200-030-100-370 | S7: Community meetings - Refreshments | T7: KaluluII | U7: Funding Source=KaluluII; Strategic Pillar=Strengthening Communities; Programme Objective=Objective 1: Promote the establishment of youth-led businesses and cooperatives, with a special focus on out of school adolescent girls and young women; Activity=Facilitate project identification and action planning in each community | V7: 2.1.3
C8: Provide matching and people’s grants to successful projects chosen by the Peer Review Committee in line with our participatory grant making guidelines | D8: Disburse 6 Matching Grants 3 communities | E8: Grants and contract management | F8: Manager CLD | G8: 6 | H8: 43350 | I8: =G8*H8 -> 260100 | J8: =I8/25 -> 10404 | K8: Q1&Q3 | L8: =I8/2 -> 130050 | N8: 130050 | P8: 5100 | Q8: Grants & Capacity Strengthening | R8: 4000-010-004 | S8: Disbursements to Grant Partners | T8: KaluluII | U8: Funding Source=KaluluII; Activity=Provide matching and people’s grants to successful projects chosen by the Peer Review Committee in line with our participatory grant making guidelines | V8: 2.1.1
C9: Sensitize the wider community and engage families youth-led businesses and cooperatives ( mixed advertisement approaches) | D9: 2 Radio adverts & 2 Social Media posts | E9: Promoting community-led development | F9: Manager CLD | G9: 1 | H9: 20000 | I9: =G9*H9 -> 20000 | J9: =I9/25 -> 800 | K9: Q1 | L9: =I9 -> 20000 | P9: 5200 | Q9: Community Engagement & Field Work | R9: 4200-030-100-370 | S9: Community meetings - Refreshments | T9: KaluluII | U9: Funding Source=KaluluII; Activity=Sensitize the wider community and engage families youth-led businesses and cooperatives ( mixed advertisement approaches) | V9: 2.1.3
C10: Provide mentorship support for managers of youth-led business and cooperatives | D10: Provided mentors with training manuals, Mentors to submit Attendance lists for meetings-Staff time | E10: Capacity Development | F10: Manager CLD | I10: =G10*H10 -> 0 | J10: =I10/25 -> 0 | K10: Q1,Q2,Q3&Q4 | P10: 5800 | Q10: Grants & Capacity Strengthening | R10: 4300-050-090-325 | T10: KaluluII | U10: Funding Source=KaluluII; Activity=Provide mentorship support for managers of youth-led business and cooperatives | V10: 2.1.1
C11: Support the formation, training and mentoring of saving groups | D11: 5 trainings per communities(Chipata, Mandevu,Chawama) | E11: Supporting community financial asset building | F11: Manager CLD | G11: 3 | H11: 19500 | I11: =G11*H11 -> 58500 | J11: =I11/25 -> 2340 | K11: Q1 | L11: =I11 -> 58500 | P11: 5400 | Q11: Training & Learning | R11: 4000-015-007-010 | S11: Conduct 5 day capacity building training | T11: KaluluII | U11: Funding Source=KaluluII; Activity=Support the formation, training and mentoring of saving groups | V11: 2.1.2
C12: Capacity development support (active citizenship, access to CDF, financial literacy, FM, technical & life skills & other demand based training) and mentorship support | D12: Youth capacited in essential business,basic financial litercay and ability to make informed economic decisions | E12: Supporting community financial asset building | F12: Manager CLD | G12: 4 | H12: 21225 | I12: =G12*H12 -> 84900 | J12: =I12/25 -> 3396 | K12: Q1,Q2,Q3&Q4 | L12: =I12/4 -> 21225 | M12: 21225 | N12: 21225 | O12: 21225 | P12: 5400 | Q12: Training & Learning | R12: 4000-015-007-010 | S12: Conduct 5 day capacity building training | T12: KaluluII | U12: Funding Source=KaluluII; Activity=Capacity development support (active citizenship, access to CDF, financial literacy, FM, technical & life skills & other demand based training) and mentorship support | V12: 2.1.2
A13: Building the Field of Community Philanthropy | C13: Provide regular communication and networking platforms | D13: 2 events twice a year | E13: Networking and partnership building | F13: Manager CLD | G13: 2 | H13: 8800 | I13: =G13*H13 -> 17600 | J13: =I13/25 -> 704 | K13: Q2&Q3 | M13: =I13/2 -> 8800 | N13: 8800 | P13: 5300 | Q13: Philanthropy, Communications & Visibility | R13: 4200-035-050 | S13: Run advocacy campaign for philanthropic giving | T13: KaluluII | U13: Funding Source=KaluluII; Strategic Pillar=Building the Field of Community Philanthropy; Activity=Provide regular communication and networking platforms | V13: 3.1.5
A14: Strengthening Communities | B14: Objective 2: Catalyse the establishment of youth-led community-based waste management businesses and cooperatives | C14: Mobilise youths engaged in informal waste collection in the targeted communities | D14: Increased participation of young people in organized waste management initiatives | E14: Promoting community-led development | F14: Manager CLD | G14: 1 | H14: 25720 | I14: =G14*H14 -> 25720 | J14: =I14/25 -> 1028.8 | K14: Q1 | L14: =I14 -> 25720 | P14: 5800 | Q14: Grants & Capacity Strengthening | R14: 4300-050-090-325 | T14: KaluluII | U14: Funding Source=KaluluII; Strategic Pillar=Strengthening Communities; Programme Objective=Objective 2: Catalyse the establishment of youth-led community-based waste management businesses and cooperatives; Activity=Mobilise youths engaged in informal waste collection in the targeted communities | V14: 2.2.1
C15: Sensitise youths about the benefits of responsible waste management. | D15: 3 cleanup meetings | E15: Promoting community-led development | F15: Manager CLD | G15: 3 | H15: 21200 | I15: =G15*H15 -> 63600 | J15: =I15/25 -> 2544 | K15: Q1,Q3&Q4 | L15: =I15/3 -> 21200 | N15: 21200 | O15: 21200 | P15: 5200 | Q15: Community Engagement & Field Work | R15: 4200-030-100-370 | S15: Community meetings - Refreshments | T15: KaluluII | U15: Funding Source=KaluluII; Activity=Sensitise youths about the benefits of responsible waste management. | V15: 2.2.3
A16: Building the Field of Community Philanthropy | C16: Engage the local council and other local stakeholders | D16: Strengthened collaboration between youth groups and local authorities on waste management initiatives. | E16: Networking and partnership building | F16: Manager CLD | G16: 4 | H16: 13650 | I16: =G16*H16 -> 54600 | J16: =I16/25 -> 2184 | K16: Q1,Q2,Q3&Q4 | L16: =I16/4 -> 13650 | M16: 13650 | N16: 13650 | O16: 13650 | P16: 5800 | Q16: Philanthropy, Communications & Visibility | R16: 4300-050-090-325 | T16: KaluluII | U16: Funding Source=KaluluII; Strategic Pillar=Building the Field of Community Philanthropy; Activity=Engage the local council and other local stakeholders | V16: 3.2.5
A17: Strengthening Communities | C17: Capacity development support (active Citizenship, financial literacy, FM, technical and life skills) and mentorship support | D17: Youth, gain essential business, financial, and civic competencies. | E17: Capacity Development | F17: Manager CLD | G17: 1 | H17: 55000 | I17: =G17*H17 -> 55000 | J17: =I17/25 -> 2200 | K17: Q2 | M17: =I17 -> 55000 | P17: 5400 | Q17: Training & Learning | R17: 4000-015-007-010 | S17: Conduct 5 day capacity building training | T17: KaluluII | U17: Funding Source=KaluluII; Strategic Pillar=Strengthening Communities; Activity=Capacity development support (active Citizenship, financial literacy, FM, technical and life skills) and mentorship support | V17: 2.2.2
C18: Facilitate project identification and action planning on waste management | D18: Youth identify viable, community-driven waste management business opportunities e.g recycling, composting, waste collection services | E18: Participatory grant making | F18: Manager CLD | G18: 3 | H18: 12680 | I18: =G18*H18 -> 38040 | J18: =I18/25 -> 1521.6 | K18: Q1 | L18: =I18 -> 38040 | P18: 5800 | Q18: Grants & Capacity Strengthening | R18: 4300-050-090-325 | T18: KaluluII | U18: Funding Source=KaluluII; Activity=Facilitate project identification and action planning on waste management | V18: 2.2.1
C19: Provide matching and people’s grants to successful projects | D19: Disburse 5 Matching grants to 3 communities | E19: Grants and contract management | F19: Manager CLD | G19: 5 | H19: 43350 | I19: =G19*H19 -> 216750 | J19: =I19/25 -> 8670 | K19: Q2 | M19: =I19 -> 216750 | P19: 5100 | Q19: Grants & Capacity Strengthening | R19: 4000-010-004 | S19: Disbursements to Grant Partners | T19: KaluluII | U19: Funding Source=KaluluII; Activity=Provide matching and people’s grants to successful projects | V19: 2.2.1
C20: Sensitise communities and engage families on waste management | D20: Increased community awareness and acceptance of youth-led waste management initiatives | E20: Promoting community-led development | G20: 4 | H20: 6185 | I20: =G20*H20 -> 24740 | J20: =I20/25 -> 989.6 | K20: Q1,Q2,Q3&Q4 | L20: =I20/4 -> 6185 | M20: 6185 | N20: 6185 | O20: 6185 | P20: 5200 | Q20: Community Engagement & Field Work | R20: 4200-030-100-370 | S20: Community meetings - Refreshments | T20: KaluluII | U20: Funding Source=KaluluII; Activity=Sensitise communities and engage families on waste management | V20: 2.2.3
A21: Building the Field of Community Philanthropy | C21: Provide regular communication and networking platforms | D21: 2 events twice a year | E21: Networking and partnership building | F21: Manager CLD | G21: 2 | H21: 8800 | I21: =G21*H21 -> 17600 | J21: =I21/25 -> 704 | K21: Q2&Q3 | M21: =I21/2 -> 8800 | N21: 8800 | P21: 5300 | Q21: Philanthropy, Communications & Visibility | R21: 4200-035-050 | S21: Run advocacy campaign for philanthropic giving | T21: KaluluII | U21: Funding Source=KaluluII; Strategic Pillar=Building the Field of Community Philanthropy; Activity=Provide regular communication and networking platforms | V21: 3.2.5
